<sdf version='1.6'>
  <model name='PONGBOT_LEG2_V1'>
    <link name='GUIDE'>
      <pose frame=''>0 0 0 0 -0 0</pose>
      <inertial>
        <pose frame=''>-0.12601 -0.059415 0.52872 0 -0 0</pose>
        <mass>16.422</mass>
        <inertia>
          <ixx>5.3916</ixx>
          <ixy>7.3108e-05</ixy>
          <ixz>2.4487e-07</ixz>
          <iyy>6.1352</iyy>
          <iyz>0.038464</iyz>
          <izz>5.5197</izz>
        </inertia>
      </inertial>
      <collision name='GUIDE_collision'>
        <pose frame=''>0 0 0 0 -0 0</pose>
        <geometry>
          <mesh>
            <scale>1 1 1</scale>
            <uri>model://PONGBOT_LEG2_V1/meshes/GUIDE.STL</uri>
          </mesh>
        </geometry>
      </collision>
      <visual name='GUIDE_visual'>
        <pose frame=''>0 0 0 0 -0 0</pose>
        <geometry>
          <mesh>
            <scale>1 1 1</scale>
            <uri>model://PONGBOT_LEG2_V1/meshes/GUIDE.STL</uri>
          </mesh>
        </geometry>
      </visual>
    </link>
    <link name='BODY'>
      <pose frame=''>-0.14694 -0.1075 0.63127 0 0 -0</pose>
      <inertial>
        <pose frame=''>0.02075 0.10543 0.08957 0 -0 0</pose>
        <mass>8.82</mass>
        <inertia>
          <ixx>0.0533535</ixx>
          <ixy>0.00021442</ixy>
          <ixz>0.00014588</ixz>
          <iyy>0.0635838</iyy>
          <iyz>0.0016175</iyz>
          <izz>0.0460113</izz>
        </inertia>
      </inertial>
      <collision name='BODY_collision'>
        <pose frame=''>0 0 0 0 -0 0</pose>
        <geometry>
          <mesh>
            <scale>1 1 1</scale>
            <uri>model://PONGBOT_LEG2_V1/meshes/BODY.STL</uri>
          </mesh>
        </geometry>
      </collision>
      <visual name='BODY_visual'>
        <pose frame=''>0 0 0 0 -0 0</pose>
        <geometry>
          <mesh>
            <scale>1 1 1</scale>
            <uri>model://PONGBOT_LEG2_V1/meshes/BODY.STL</uri>
          </mesh>
        </geometry>
      </visual>
    </link>
    <joint name='PRISMATIC_JOINT1' type='prismatic'>
      <child>BODY</child>
      <parent>GUIDE</parent>
      <axis>
        <xyz>-0 -0 1</xyz>
        <limit>
          <lower>0</lower>
          <upper>0</upper>
          <effort>1000</effort>
          <velocity>0</velocity>
        </limit>
        <dynamics>
          <spring_reference>0</spring_reference>
          <spring_stiffness>0</spring_stiffness>
        </dynamics>
        <use_parent_model_frame>1</use_parent_model_frame>
      </axis>
    </joint>
    <link name='HIP_ROLL'>
      <pose frame=''>-0.0284 -0.1075 0.63127 -0 -0 0</pose>
      <inertial>
        <pose frame=''>-0.01895 0.00091 0.00575 0 -0 0</pose>
        <mass>3.04</mass>
        <inertia>
          <ixx>0.0028285</ixx>
          <ixy>3.146e-05</ixy>
          <ixz>0.00016348</ixz>
          <iyy>0.0046547</iyy>
          <iyz>6.915e-05</iyz>
          <izz>0.0041943</izz>
        </inertia>
      </inertial>
      <collision name='HIP_ROLL_collision'>
        <pose frame=''>0 0 0 0 -0 0</pose>
        <geometry>
          <mesh>
            <scale>1 1 1</scale>
            <uri>model://PONGBOT_LEG2_V1/meshes/HIP_ROLL.STL</uri>
          </mesh>
        </geometry>
      </collision>
      <visual name='HIP_ROLL_visual'>
        <pose frame=''>0 0 0 0 -0 0</pose>
        <geometry>
          <mesh>
            <scale>1 1 1</scale>
            <uri>model://PONGBOT_LEG2_V1/meshes/HIP_ROLL.STL</uri>
          </mesh>
        </geometry>
      </visual>
    </link>
    <joint name='HIP_ROLL_FIXED_JOINT' type='revolute'>
      <child>HIP_ROLL</child>
      <parent>BODY</parent>
      <axis>
        <xyz>-1 -0 -0</xyz>
        <limit>
          <lower>0</lower>
          <upper>0</upper>
          <effort>0</effort>
          <velocity>0</velocity>
        </limit>
        <dynamics>
          <spring_reference>0</spring_reference>
          <spring_stiffness>0</spring_stiffness>
        </dynamics>
        <use_parent_model_frame>1</use_parent_model_frame>
      </axis>
    </joint>
    <link name='HIP_PITCH'>
      <pose frame=''>-0.0284 -0.1075 0.63127 -0 -0 0</pose>
      <inertial>
        <pose frame=''>-0.11939 -0.00014 -0.00018 0 -0 0</pose>
        <mass>1.12</mass>
        <inertia>
          <ixx>0.00112502</ixx>
          <ixy>3.169e-05</ixy>
          <ixz>-1.89e-05</ixz>
          <iyy>0.00121279</iyy>
          <iyz>1.516e-05</iyz>
          <izz>0.00123075</izz>
        </inertia>
      </inertial>
      <collision name='HIP_PITCH_collision'>
        <pose frame=''>0 0 0 0 -0 0</pose>
        <geometry>
          <mesh>
            <scale>1 1 1</scale>
            <uri>model://PONGBOT_LEG2_V1/meshes/HIP_PITCH.STL</uri>
          </mesh>
        </geometry>
      </collision>
      <visual name='HIP_PITCH_visual'>
        <pose frame=''>0 0 0 0 -0 0</pose>
        <geometry>
          <mesh>
            <scale>1 1 1</scale>
            <uri>model://PONGBOT_LEG2_V1/meshes/HIP_PITCH.STL</uri>
          </mesh>
        </geometry>
      </visual>
    </link>
    <joint name='HIP_ROLL_JOINT' type='revolute'>
      <child>HIP_PITCH</child>
      <parent>HIP_ROLL</parent>
      <axis>
        <xyz>-1 -0 -0</xyz>
        <limit>
          <lower>-3.14</lower>
          <upper>3.14</upper>
          <effort>1000</effort>
          <velocity>0</velocity>
        </limit>
        <dynamics>
          <spring_reference>0</spring_reference>
          <spring_stiffness>0</spring_stiffness>
        </dynamics>
        <use_parent_model_frame>1</use_parent_model_frame>
      </axis>
    </joint>
    <link name='KNEE'>
      <pose frame=''>-0.14694 -0.1075 0.63127 0 0 -0</pose>
      <inertial>
        <pose frame=''>0.00078 -0.09087 -0.02665 0 -0 0</pose>
        <mass>1.98</mass>
        <inertia>
          <ixx>0.0119838</ixx>
          <ixy>-6.831e-05</ixy>
          <ixz>4.11e-06</ixz>
          <iyy>0.0123972</iyy>
          <iyz>0.00073063</iyz>
          <izz>0.00202463</izz>
        </inertia>
      </inertial>
      <collision name='KNEE_collision'>
        <pose frame=''>0 0 0 0 -0 0</pose>
        <geometry>
          <mesh>
            <scale>1 1 1</scale>
            <uri>model://PONGBOT_LEG2_V1/meshes/KNEE.STL</uri>
          </mesh>
        </geometry>
      </collision>
      <visual name='KNEE_visual'>
        <pose frame=''>0 0 0 0 -0 0</pose>
        <geometry>
          <mesh>
            <scale>1 1 1</scale>
            <uri>model://PONGBOT_LEG2_V1/meshes/KNEE.STL</uri>
          </mesh>
        </geometry>
      </visual>
    </link>
    <joint name='HIP_PITCH_JOINT' type='revolute'>
      <child>KNEE</child>
      <parent>HIP_PITCH</parent>
      <axis>
        <xyz>0 1 0.002736</xyz>
        <limit>
          <lower>-3.14</lower>
          <upper>3.14</upper>
          <effort>1000</effort>
          <velocity>0</velocity>
        </limit>
        <dynamics>
          <spring_reference>0</spring_reference>
          <spring_stiffness>0</spring_stiffness>
        </dynamics>
        <use_parent_model_frame>1</use_parent_model_frame>
      </axis>
    </joint>
    <link name='ROTATOR'>
      <pose frame=''>-0.14694 -0.2125 0.630983 -0 -0 0</pose>
      <inertial>
        <pose frame=''>-0.002099 -0.023669 -0.005832 0 -0 0</pose>
        <mass>0.072049</mass>
        <inertia>
          <ixx>5.7062e-05</ixx>
          <ixy>8.078e-08</ixy>
          <ixz>5.6783e-06</ixz>
          <iyy>9.9919e-05</iyy>
          <iyz>1.1036e-07</iyz>
          <izz>4.3528e-05</izz>
        </inertia>
      </inertial>
      <collision name='ROTATOR_collision'>
        <pose frame=''>0 0 0 0 -0 0</pose>
        <geometry>
          <mesh>
            <scale>1 1 1</scale>
            <uri>model://PONGBOT_LEG2_V1/meshes/ROTATOR.STL</uri>
          </mesh>
        </geometry>
      </collision>
      <visual name='ROTATOR_visual'>
        <pose frame=''>0 0 0 0 -0 0</pose>
        <geometry>
          <mesh>
            <scale>1 1 1</scale>
            <uri>model://PONGBOT_LEG2_V1/meshes/ROTATOR.STL</uri>
          </mesh>
        </geometry>
      </visual>
    </link>
    <joint name='KNEE_JOINT' type='revolute'>
      <child>ROTATOR</child>
      <parent>KNEE</parent>
      <axis>
        <xyz>-0 1 0.002736</xyz>
        <limit>
          <lower>-3.14</lower>
          <upper>3.14</upper>
          <effort>1000</effort>
          <velocity>0</velocity>
        </limit>
        <dynamics>
          <spring_reference>0</spring_reference>
          <spring_stiffness>0</spring_stiffness>
        </dynamics>
        <use_parent_model_frame>1</use_parent_model_frame>
      </axis>
    </joint>
    <link name='LOAD_BAR'>
      <pose frame=''>-0.164041 -0.245746 0.583907 -0 -0 0</pose>
      <inertial>
        <pose frame=''>0 0.000373 -0.1525 0 -0 0</pose>
        <mass>0.20473</mass>
        <inertia>
          <ixx>0.0017929</ixx>
          <ixy>1.3688e-13</ixy>
          <ixz>3.716e-16</ixz>
          <iyy>0.0017932</iyy>
          <iyz>-3.5294e-06</iyz>
          <izz>2.9094e-06</izz>
        </inertia>
      </inertial>
      <collision name='LOAD_BAR_collision'>
        <pose frame=''>0 0 0 0 -0 0</pose>
        <geometry>
          <mesh>
            <scale>1 1 1</scale>
            <uri>model://PONGBOT_LEG2_V1/meshes/LOAD_BAR.STL</uri>
          </mesh>
        </geometry>
      </collision>
      <visual name='LOAD_BAR_visual'>
        <pose frame=''>0 0 0 0 -0 0</pose>
        <geometry>
          <mesh>
            <scale>1 1 1</scale>
            <uri>model://PONGBOT_LEG2_V1/meshes/LOAD_BAR.STL</uri>
          </mesh>
        </geometry>
      </visual>
    </link>
    <joint name='LOAD_BAR_JOINT' type='revolute'>
      <child>LOAD_BAR</child>
      <parent>ROTATOR</parent>
      <axis>
        <xyz>-0 1 0.002736</xyz>
        <limit>
          <lower>-3.14</lower>
          <upper>3.14</upper>
          <effort>1000</effort>
          <velocity>0</velocity>
        </limit>
        <dynamics>
          <spring_reference>0</spring_reference>
          <spring_stiffness>0</spring_stiffness>
        </dynamics>
        <use_parent_model_frame>1</use_parent_model_frame>
      </axis>
    </joint>
    <link name='CALF'>
      <pose frame=''>-0.164041 -0.246037 0.278907 -0 -0 0</pose>
      <inertial>
        <pose frame=''>0.017157 0.032869 0.004905 0 -0 0</pose>
        <mass>0.2318</mass>
        <inertia>
          <ixx>0.00099232</ixx>
          <ixy>2.721e-06</ixy>
          <ixz>2.9071e-06</ixz>
          <iyy>0.00095518</iyy>
          <iyz>-1.2222e-05</iyz>
          <izz>8.7128e-05</izz>
        </inertia>
      </inertial>
      <collision name='CALF_collision'>
        <pose frame=''>0 0 0 0 -0 0</pose>
        <geometry>
          <mesh>
            <scale>1 1 1</scale>
            <uri>model://PONGBOT_LEG2_V1/meshes/CALF.STL</uri>
          </mesh>
        </geometry>
      </collision>
      <visual name='CALF_visual'>
        <pose frame=''>0 0 0 0 -0 0</pose>
        <geometry>
          <mesh>
            <scale>1 1 1</scale>
            <uri>model://PONGBOT_LEG2_V1/meshes/CALF.STL</uri>
          </mesh>
        </geometry>
      </visual>
    </link>
    <joint name='CARF_JOINT' type='revolute'>
      <child>CALF</child>
      <parent>LOAD_BAR</parent>
      <axis>
        <xyz>-0 1 0.002736</xyz>
        <limit>
          <lower>-3.14</lower>
          <upper>3.14</upper>
          <effort>1000</effort>
          <velocity>0</velocity>
        </limit>
        <dynamics>
          <spring_reference>0</spring_reference>
          <spring_stiffness>0</spring_stiffness>
        </dynamics>
        <use_parent_model_frame>1</use_parent_model_frame>
      </axis>
    </joint>
    <link name='FOOT'>
      <pose frame=''>-0.14694 -0.21096 0.067987 -0 -0 0</pose>
      <inertial>
        <pose frame=''>0.018482 5.6e-05 -0.024031 0 -0 0</pose>
        <mass>0.088034</mass>
        <inertia>
          <ixx>3.4452e-05</ixx>
          <ixy>1.8417e-08</ixy>
          <ixz>-6.1903e-06</ixz>
          <iyy>3.9339e-05</iyy>
          <iyz>-2.578e-08</iyz>
          <izz>3.0198e-05</izz>
        </inertia>
      </inertial>
      <collision name='FOOT_collision'>
        <pose frame=''>0 0 0 0 -0 0</pose>
        <geometry>
          <mesh>
            <scale>1 1 1</scale>
            <uri>model://PONGBOT_LEG2_V1/meshes/FOOT.STL</uri>
          </mesh>
        </geometry>
      </collision>
      <visual name='FOOT_visual'>
        <pose frame=''>0 0 0 0 -0 0</pose>
        <geometry>
          <mesh>
            <scale>1 1 1</scale>
            <uri>model://PONGBOT_LEG2_V1/meshes/FOOT.STL</uri>
          </mesh>
        </geometry>
      </visual>
    </link>
    <joint name='FOOT_JOINT' type='revolute'>
      <child>FOOT</child>
      <parent>CALF</parent>
      <axis>
        <xyz>-0 1 0.002736</xyz>
        <limit>
          <lower>0</lower>
          <upper>0</upper>
          <effort>1000</effort>
          <velocity>0</velocity>
        </limit>
        <dynamics>
          <spring_reference>0</spring_reference>
          <spring_stiffness>0</spring_stiffness>
        </dynamics>
        <use_parent_model_frame>1</use_parent_model_frame>
      </axis>
    </joint>
  </model>
</sdf>
