<robot
  name="PONGBOT_LEG2_V1">
  <link
    name="GUIDE">
    <inertial>
      <origin
        xyz="-0.12601 -0.059415 0.52872"
        rpy="0 0 0" />
      <mass
        value="16.422" />
      <inertia
        ixx="5.3916"
        ixy="7.3108E-05"
        ixz="2.4487E-07"
        iyy="6.1352"
        iyz="0.038464"
        izz="5.5197" />
    </inertial>
    <visual>
      <origin
        xyz="0 0 0"
        rpy="0 0 0" />
      <geometry>
        <mesh
          filename="package://PONGBOT_LEG2_V1/meshes/GUIDE.STL" />
      </geometry>
      <material
        name="">
        <color
          rgba="0.79216 0.81961 0.93333 1" />
      </material>
    </visual>
    <collision>
      <origin
        xyz="0 0 0"
        rpy="0 0 0" />
      <geometry>
        <mesh
          filename="package://PONGBOT_LEG2_V1/meshes/GUIDE.STL" />
      </geometry>
    </collision>
  </link>
  <link
    name="BODY">
    <inertial>
      <origin
        xyz="0.02075 0.10543 0.08957"
        rpy="0 0 0" />
      <mass
        value="8.82" />
      <inertia
        ixx="0.05335354"
        ixy="0.00021442"
        ixz="0.00014588"
        iyy="0.06358379"
        iyz="0.0016175"
        izz="0.0460113" />
    </inertial>
    <visual>
      <origin
        xyz="0 0 0"
        rpy="0 0 0" />
      <geometry>
        <mesh
          filename="package://PONGBOT_LEG2_V1/meshes/BODY.STL" />
      </geometry>
      <material
        name="">
        <color
          rgba="0.75294 0.75294 0.75294 1" />
      </material>
    </visual>
    <collision>
      <origin
        xyz="0 0 0"
        rpy="0 0 0" />
      <geometry>
        <mesh
          filename="package://PONGBOT_LEG2_V1/meshes/BODY.STL" />
      </geometry>
    </collision>
  </link>
  <joint
    name="PRISMATIC_JOINT1"
    type="prismatic">
    <origin
      xyz="-0.14694 -0.1075 0.63127"
      rpy="2.4639E-15 1.2771E-29 -5.1834E-15" />
    <parent
      link="GUIDE" />
    <child
      link="BODY" />
    <axis
      xyz="0 0 1" />
    <limit
      lower="0"
      upper="0"
      effort="1000"
      velocity="0" />
  </joint>
  <link
    name="HIP_ROLL">
    <inertial>
      <origin
        xyz="-0.01895 0.00091 0.00575"
        rpy="0 0 0" />
      <mass
        value="3.04" />
      <inertia
        ixx="0.0028285"
        ixy="3.146E-05"
        ixz="0.00016348"
        iyy="0.0046547"
        iyz="6.915E-05"
        izz="0.0041943" />
    </inertial>
    <visual>
      <origin
        xyz="0 0 0"
        rpy="0 0 0" />
      <geometry>
        <mesh
          filename="package://PONGBOT_LEG2_V1/meshes/HIP_ROLL.STL" />
      </geometry>
      <material
        name="">
        <color
          rgba="0.75294 0.75294 0.75294 1" />
      </material>
    </visual>
    <collision>
      <origin
        xyz="0 0 0"
        rpy="0 0 0" />
      <geometry>
        <mesh
          filename="package://PONGBOT_LEG2_V1/meshes/HIP_ROLL.STL" />
      </geometry>
    </collision>
  </link>
  <joint
    name="HIP_ROLL_FIXED_JOINT"
    type="revolute">
    <origin
      xyz="0.11854 0 0"
      rpy="-2.4639E-15 0 5.1834E-15" />
    <parent
      link="BODY" />
    <child
      link="HIP_ROLL" />
    <axis
      xyz="-1 0 0" />
    <limit
      lower="0"
      upper="0"
      effort="0"
      velocity="0" />
  </joint>
  <link
    name="HIP_PITCH">
    <inertial>
      <origin
        xyz="-0.11939 -0.00014 -0.00018"
        rpy="0 0 0" />
      <mass
        value="1.12" />
      <inertia
        ixx="0.00112502"
        ixy="3.169E-05"
        ixz="-1.89E-05"
        iyy="0.00121279"
        iyz="1.516E-05"
        izz="0.00123075" />
    </inertial>
    <visual>
      <origin
        xyz="0 0 0"
        rpy="0 0 0" />
      <geometry>
        <mesh
          filename="package://PONGBOT_LEG2_V1/meshes/HIP_PITCH.STL" />
      </geometry>
      <material
        name="">
        <color
          rgba="0.75294 0.75294 0.75294 1" />
      </material>
    </visual>
    <collision>
      <origin
        xyz="0 0 0"
        rpy="0 0 0" />
      <geometry>
        <mesh
          filename="package://PONGBOT_LEG2_V1/meshes/HIP_PITCH.STL" />
      </geometry>
    </collision>
  </link>
  <joint
    name="HIP_ROLL_JOINT"
    type="revolute">
    <origin
      xyz="0 0 0"
      rpy="0 0 0" />
    <parent
      link="HIP_ROLL" />
    <child
      link="HIP_PITCH" />
    <axis
      xyz="-1 0 0" />
    <limit
      lower="-3.14"
      upper="3.14"
      effort="1000"
      velocity="0" />
  </joint>
  <link
    name="KNEE">
    <inertial>
      <origin
        xyz="0.00078 -0.09087 -0.02665"
        rpy="0 0 0" />
      <mass
        value="1.98" />
      <inertia
        ixx="0.01198379"
        ixy="-6.831E-05"
        ixz="4.11E-06"
        iyy="0.01239722"
        iyz="0.00073063"
        izz="0.00202463" />
    </inertial>
    <visual>
      <origin
        xyz="0 0 0"
        rpy="0 0 0" />
      <geometry>
        <mesh
          filename="package://PONGBOT_LEG2_V1/meshes/KNEE.STL" />
      </geometry>
      <material
        name="">
        <color
          rgba="0.75294 0.75294 0.75294 1" />
      </material>
    </visual>
    <collision>
      <origin
        xyz="0 0 0"
        rpy="0 0 0" />
      <geometry>
        <mesh
          filename="package://PONGBOT_LEG2_V1/meshes/KNEE.STL" />
      </geometry>
    </collision>
  </link>
  <joint
    name="HIP_PITCH_JOINT"
    type="revolute">
    <origin
      xyz="-0.11854 0 0"
      rpy="2.4639E-15 1.2771E-29 -5.1834E-15" />
    <parent
      link="HIP_PITCH" />
    <child
      link="KNEE" />
    <axis
      xyz="0 1 0.0027355" />
    <limit
      lower="-3.14"
      upper="3.14"
      effort="1000"
      velocity="0" />
  </joint>
  <link
    name="ROTATOR">
    <inertial>
      <origin
        xyz="-0.0020991 -0.023669 -0.005832"
        rpy="0 0 0" />
      <mass
        value="0.072049" />
      <inertia
        ixx="5.7062E-05"
        ixy="8.078E-08"
        ixz="5.6783E-06"
        iyy="9.9919E-05"
        iyz="1.1036E-07"
        izz="4.3528E-05" />
    </inertial>
    <visual>
      <origin
        xyz="0 0 0"
        rpy="0 0 0" />
      <geometry>
        <mesh
          filename="package://PONGBOT_LEG2_V1/meshes/ROTATOR.STL" />
      </geometry>
      <material
        name="">
        <color
          rgba="0.89804 0.91765 0.92941 1" />
      </material>
    </visual>
    <collision>
      <origin
        xyz="0 0 0"
        rpy="0 0 0" />
      <geometry>
        <mesh
          filename="package://PONGBOT_LEG2_V1/meshes/ROTATOR.STL" />
      </geometry>
    </collision>
  </link>
  <joint
    name="KNEE_JOINT"
    type="revolute">
    <origin
      xyz="0 -0.105 -0.00028723"
      rpy="-2.4639E-15 0 5.1834E-15" />
    <parent
      link="KNEE" />
    <child
      link="ROTATOR" />
    <axis
      xyz="0 1 0.0027355" />
    <limit
      lower="-3.14"
      upper="3.14"
      effort="1000"
      velocity="0" />
  </joint>
  <link
    name="LOAD_BAR">
    <inertial>
      <origin
        xyz="1.5248E-08 0.00037331 -0.1525"
        rpy="0 0 0" />
      <mass
        value="0.20473" />
      <inertia
        ixx="0.0017929"
        ixy="1.3688E-13"
        ixz="3.716E-16"
        iyy="0.0017932"
        iyz="-3.5294E-06"
        izz="2.9094E-06" />
    </inertial>
    <visual>
      <origin
        xyz="0 0 0"
        rpy="0 0 0" />
      <geometry>
        <mesh
          filename="package://PONGBOT_LEG2_V1/meshes/LOAD_BAR.STL" />
      </geometry>
      <material
        name="">
        <color
          rgba="0.64706 0.61961 0.58824 1" />
      </material>
    </visual>
    <collision>
      <origin
        xyz="0 0 0"
        rpy="0 0 0" />
      <geometry>
        <mesh
          filename="package://PONGBOT_LEG2_V1/meshes/LOAD_BAR.STL" />
      </geometry>
    </collision>
  </link>
  <joint
    name="LOAD_BAR_JOINT"
    type="revolute">
    <origin
      xyz="-0.017101 -0.033246 -0.047076"
      rpy="0 0 0" />
    <parent
      link="ROTATOR" />
    <child
      link="LOAD_BAR" />
    <axis
      xyz="0 1 0.0027355" />
    <limit
      lower="-3.14"
      upper="3.14"
      effort="1000"
      velocity="0" />
  </joint>
  <link
    name="CALF">
    <inertial>
      <origin
        xyz="0.017157 0.032869 0.004905"
        rpy="0 0 0" />
      <mass
        value="0.2318" />
      <inertia
        ixx="0.00099232"
        ixy="2.721E-06"
        ixz="2.9071E-06"
        iyy="0.00095518"
        iyz="-1.2222E-05"
        izz="8.7128E-05" />
    </inertial>
    <visual>
      <origin
        xyz="0 0 0"
        rpy="0 0 0" />
      <geometry>
        <mesh
          filename="package://PONGBOT_LEG2_V1/meshes/CALF.STL" />
      </geometry>
      <material
        name="">
        <color
          rgba="0.22353 0.22353 0.22353 1" />
      </material>
    </visual>
    <collision>
      <origin
        xyz="0 0 0"
        rpy="0 0 0" />
      <geometry>
        <mesh
          filename="package://PONGBOT_LEG2_V1/meshes/CALF.STL" />
      </geometry>
    </collision>
  </link>
  <joint
    name="CARF_JOINT"
    type="revolute">
    <origin
      xyz="0 -0.00029067 -0.305"
      rpy="0 0 0" />
    <parent
      link="LOAD_BAR" />
    <child
      link="CALF" />
    <axis
      xyz="0 1 0.0027355" />
    <limit
      lower="-3.14"
      upper="3.14"
      effort="1000"
      velocity="0" />
  </joint>
  <link
    name="FOOT">
    <inertial>
      <origin
        xyz="0.018482 5.5541E-05 -0.024031"
        rpy="0 0 0" />
      <mass
        value="0.088034" />
      <inertia
        ixx="3.4452E-05"
        ixy="1.8417E-08"
        ixz="-6.1903E-06"
        iyy="3.9339E-05"
        iyz="-2.578E-08"
        izz="3.0198E-05" />
    </inertial>
    <visual>
      <origin
        xyz="0 0 0"
        rpy="0 0 0" />
      <geometry>
        <mesh
          filename="package://PONGBOT_LEG2_V1/meshes/FOOT.STL" />
      </geometry>
      <material
        name="">
        <color
          rgba="0.79216 0.81961 0.93333 1" />
      </material>
    </visual>
    <collision>
      <origin
        xyz="0 0 0"
        rpy="0 0 0" />
      <geometry>
        <mesh
          filename="package://PONGBOT_LEG2_V1/meshes/FOOT.STL" />
      </geometry>
    </collision>
  </link>
  <joint
    name="FOOT_JOINT"
    type="revolute">
    <origin
      xyz="0.017101 0.035077 -0.21092"
      rpy="0 0 0" />
    <parent
      link="CALF" />
    <child
      link="FOOT" />
    <axis
      xyz="0 1 0.0027355" />
    <limit
      lower="0"
      upper="0"
      effort="1000"
      velocity="0" />
  </joint>
</robot>