<?xml version="1.0" ?>
<sdf version='1.6'>
  <model name='PONGBOT_Q_V6'>
    <link name='BODY'>
      <pose frame=''>0 0 0 0 -0 0</pose>
      <inertial>
        <pose frame=''>-0.0221 0.00034 0.05293 0 -0 0</pose>
        <mass>24.701</mass>
        <inertia>
          <ixx>0.34089</ixx>
          <ixy>-0.00272</ixy>
          <ixz>-0.08697</ixz>
          <iyy>1.8849</iyy>
          <iyz>0.00032</iyz>
          <izz>1.9898</izz>
        </inertia>
      </inertial>
      <!--collision name='BODY_collision'>
        <pose frame=''>0 0 0 0 -0 0</pose>
        <geometry>
          <mesh>
            <scale>1 1 1</scale>
            <uri>model://PONGBOT_Q_V6/meshes/BODY.STL</uri>
          </mesh>
        </geometry>
      </collision-->
      <visual name='BODY_visual'>
        <pose frame=''>0 0 0 0 -0 0</pose>
        <geometry>
          <mesh>
            <scale>1 1 1</scale>
            <uri>model://PONGBOT_Q_V6/meshes/BODY.STL</uri>
          </mesh>
        </geometry>
         <material>
          <ambient>97 97 97 1</ambient>
          <diffuse>1 1 1 1</diffuse>
          <emissive>0 0 0 0</emissive>
          <specular>0 0 0 0</specular>
        </material>
      </visual>
      <sensor name='IMU' type='imu'>
        <pose frame=''>0.0 0 0 0 -0 0</pose>
        <imu>
          <angular_velocity>
            <x>
              <noise type='none'></noise>
              <!-- <noise type='gaussian'>
                <mean>0</mean>
                <stddev>0.5</stddev>
              </noise> -->
            </x>
            <y>
              <noise type='none'></noise>
              <!-- <noise type='gaussian'>
                <mean>0</mean>
                <stddev>0.5</stddev>
              </noise> -->
            </y>
            <z>
              <noise type='none'></noise>
              <!-- <noise type='gaussian'>
                <mean>0</mean>
                <stddev>0.5</stddev>
              </noise> -->
            </z>
          </angular_velocity>
          <linear_acceleration>
            <x>
              <noise type='none'></noise>
              <!-- <noise type='gaussian'>
                <mean>0</mean>
                <stddev>0.1</stddev>
              </noise> -->
            </x>
            <y>
              <noise type="none"></noise>
              <!-- <noise type='gaussian'>
                <mean>0</mean>
                <stddev>0.1</stddev>
              </noise> -->
            </y>
            <z>
              <noise type='none'></noise>
              <!-- <noise type='gaussian'>
                <mean>0</mean>
                <stddev>0.1</stddev>
              </noise> -->
            </z>
          </linear_acceleration>
        </imu>
        <always_on>1</always_on>
        <update_rate>1000</update_rate>
        <visualize>true</visualize>
      </sensor>
    </link>
    <link name='FL_HIP'>
      <pose frame=''>0.35 0.11502 0 0 -0 0</pose>
      <inertial>
        <pose frame=''>0.00113 -0.00546 0.00059 0 -0 0</pose>
        <mass>1.5346</mass>
        <inertia>
          <ixx>0.00131</ixx>
          <ixy>0</ixy>
          <ixz>1e-05</ixz>
          <iyy>0.00176</iyy>
          <iyz>-1e-05</iyz>
          <izz>0.00141</izz>
        </inertia>
      </inertial>
      <!--collision name='FL_HIP_collision'>
        <pose frame=''>0 0 0 0 -0 0</pose>
        <geometry>
          <mesh>
            <scale>1 1 1</scale>
            <uri>model://PONGBOT_Q_V6/meshes/FL_HIP.STL</uri>
          </mesh>
        </geometry>
      </collision-->
      <visual name='FL_HIP_visual'>
        <pose frame=''>0 0 0 0 -0 0</pose>
        <geometry>
          <mesh>
            <scale>1 1 1</scale>
            <uri>model://PONGBOT_Q_V6/meshes/FL_HIP.STL</uri>
          </mesh>
        </geometry>
       <material>
          <ambient>213 0 0 1</ambient>
          <diffuse>1 1 1 1</diffuse>
          <emissive>0 0 0 1</emissive>
          <specular>0 0 0 0</specular>
        </material>
      </visual>
    </link>
    <joint name='FL_HR_JOINT' type='revolute'>
      <child>FL_HIP</child>
      <parent>BODY</parent>
      <axis>
        <xyz>1 0 0</xyz>
        <limit>
          <lower>-1e+16</lower>
          <upper>1e+16</upper>
        </limit>
        <dynamics>
          <spring_reference>0</spring_reference>
          <spring_stiffness>0</spring_stiffness>
        </dynamics>
        <use_parent_model_frame>1</use_parent_model_frame>
      </axis>
    </joint>
    <link name='FL_THIGH'>
      <pose frame=''>0.35 0.21992 0 0 -0 0</pose>
      <inertial>
        <pose frame=''>0.00018 -0.01146 -0.02836 0 -0 0</pose>
        <mass>3.32</mass>
        <inertia>
          <ixx>0.02493</ixx>
          <ixy>-3e-05</ixy>
          <ixz>2e-05</ixz>
          <iyy>0.02533</iyy>
          <iyz>-0.001</iyz>
          <izz>0.00394</izz>
        </inertia>
      </inertial>
      <!--collision name='FL_THIGH_collision'>
        <pose frame=''>0 0 0 0 -0 0</pose>
        <geometry>
          <mesh>
            <scale>1 1 1</scale>
            <uri>model://PONGBOT_Q_V6/meshes/FL_THIGH.STL</uri>
          </mesh>
        </geometry>
      </collision-->
      <visual name='FL_THIGH_visual'>
        <pose frame=''>0 0 0 0 -0 0</pose>
        <geometry>
          <mesh>
            <scale>1 1 1</scale>
            <uri>model://PONGBOT_Q_V6/meshes/FL_THIGH.STL</uri>
          </mesh>
        </geometry>
        <material>
          <ambient>213 0 0 1</ambient>
          <diffuse>1 1 1 1</diffuse>
          <emissive>0 0 0 1</emissive>
          <specular>0 0 0 0</specular>
        </material>
      </visual>
    </link>
    <joint name='FL_HP_JOINT' type='revolute'>
      <child>FL_THIGH</child>
      <parent>FL_HIP</parent>
      <axis>
        <xyz>0 1 0</xyz>
        <limit>
          <lower>-1e+16</lower>
          <upper>1e+16</upper>
        </limit>
        <dynamics>
          <spring_reference>0</spring_reference>
          <spring_stiffness>0</spring_stiffness>
        </dynamics>
        <use_parent_model_frame>1</use_parent_model_frame>
      </axis>
    </joint>
    <link name='FL_CALF'>
      <pose frame=''>0.35 0.21992 -0.305 0 -0 0</pose>
      <inertial>
        <pose frame=''>0.03375 0.00334 -0.0746 0 -0 0</pose>
        <mass>0.57335</mass>
        <inertia>
          <ixx>0.00434</ixx>
          <ixy>-7e-05</ixy>
          <ixz>-0.00216</ixz>
          <iyy>0.00538</iyy>
          <iyz>0.00018</iyz>
          <izz>0.00139</izz>
        </inertia>
      </inertial>
      <!--collision name='FL_CALF_collision'>
        <pose frame=''>0 0 0 0 -0 0</pose>
        <geometry>
          <mesh>
            <scale>1 1 1</scale>
            <uri>model://PONGBOT_Q_V6/meshes/FL_CALF.STL</uri>
          </mesh>
        </geometry>
      </collision-->
      <visual name='FL_CALF_visual'>
        <pose frame=''>0 0 0 0 -0 0</pose>
        <geometry>
          <mesh>
            <scale>1 1 1</scale>
            <uri>model://PONGBOT_Q_V6/meshes/FL_CALF.STL</uri>
          </mesh>
        </geometry>
       <material>
          <ambient>33 33 33 1</ambient>
          <diffuse>1 1 1 1</diffuse>
          <emissive>0 0 0 1</emissive>
          <specular>0 0 0 0</specular>
        </material>
      </visual>
    </link>
    <joint name='FL_KN_JOINT' type='revolute'>
      <child>FL_CALF</child>
      <parent>FL_THIGH</parent>
      <axis>
        <xyz>0 1 0</xyz>
        <limit>
          <lower>-1e+16</lower>
          <upper>1e+16</upper>
        </limit>
        <dynamics>
          <spring_reference>0</spring_reference>
          <spring_stiffness>0</spring_stiffness>
        </dynamics>
        <use_parent_model_frame>1</use_parent_model_frame>
      </axis>
    </joint>
    <link name='FL_TIP'>
      <pose frame=''>0.46836 0.21992 -0.56773 0 -0 0</pose>
      <inertial>
        <pose frame=''>-0.00076 0 0.00289 0 -0 0</pose>
        <mass>0.1646</mass>
        <inertia>
          <ixx>9e-05</ixx>
          <ixy>0</ixy>
          <ixz>-1e-05</ixz>
          <iyy>9e-05</iyy>
          <iyz>0</iyz>
          <izz>8e-05</izz>
        </inertia>
      </inertial>
      <collision name='FL_TIP_collision'>
        <pose frame=''>0 0 0 1.57 -0 0</pose>
        <geometry>
	<cylinder>
	  <radius>0.029</radius>
	  <length>0.054</length>	
	</cylinder>
          <!--mesh>
            <scale>1 1 1</scale>
            <uri>model://PONGBOT_Q_V6/meshes/FL_TIP.STL</uri>
          </mesh-->
        </geometry>
        <surface>
          <bounce>
            <restitution_coefficient> 0 </restitution_coefficient>
          </bounce>
          <friction>
            <ode>
               <mu>  1  </mu>
              <mu2> 1  </mu2>
            </ode>
          </friction>
          <contact>
            <ode>
              <!-- <soft_erp> 0.1 </soft_erp>
              <soft_cfm> 1E-4 </soft_cfm> -->
              <kp>5000000</kp>
              <kd>5000</kd>
              <max_vel>0.1</max_vel>
              <!-- <max_vel>0.01</max_vel> -->
               <min_depth>0.0001</min_depth>
              <!-- <min_depth>0.0</min_depth> -->
            </ode>
          </contact>
        </surface>
      </collision>
      <visual name='FL_TIP_visual'>
        <pose frame=''>0 0 0 0 -0 0</pose>
        <geometry>
          <mesh>
            <scale>1 1 1</scale>
            <uri>model://PONGBOT_Q_V6/meshes/FL_TIP.STL</uri>
          </mesh>
        </geometry>
      </visual>
      <sensor name="FL_TIP_contact" type='contact'>
       <contact>
         <collision>FL_TIP_collision</collision>
       </contact>
      </sensor>
    </link>
    <joint name='FL_TIP_JOINT' type='fixed'>
      <child>FL_TIP</child>
      <parent>FL_CALF</parent>
      <sensor name="FL_FT_SENSOR" type="force_torque">
        <force_torque>
          <frame>child</frame>
          <measure_direction>child_to_parent</measure_direction>
        </force_torque>
        <!-- <visualize> True </visualize> -->
      </sensor>
    </joint>
    <link name='FR_HIP'>
      <pose frame=''>0.35 -0.11502 0 0 -0 0</pose>
      <inertial>
        <pose frame=''>0.00113 0.00546 -0.00059 0 -0 0</pose>
        <mass>1.5346</mass>
        <inertia>
          <ixx>0.00131</ixx>
          <ixy>0</ixy>
          <ixz>-1e-05</ixz>
          <iyy>0.00176</iyy>
          <iyz>-1e-05</iyz>
          <izz>0.00141</izz>
        </inertia>
      </inertial>
      <!--collision name='FR_HIP_collision'>
        <pose frame=''>0 0 0 0 -0 0</pose>
        <geometry>
          <mesh>
            <scale>1 1 1</scale>
            <uri>model://PONGBOT_Q_V6/meshes/FR_HIP.STL</uri>
          </mesh>
        </geometry>
      </collision-->
      <visual name='FR_HIP_visual'>
        <pose frame=''>0 0 0 0 -0 0</pose>
        <geometry>
          <mesh>
            <scale>1 1 1</scale>
            <uri>model://PONGBOT_Q_V6/meshes/FR_HIP.STL</uri>
          </mesh>
        </geometry>
        <material>
          <ambient>213 0 0 1</ambient>
          <diffuse>1 1 1 1</diffuse>
          <emissive>0 0 0 1</emissive>
          <specular>0 0 0 0</specular>
        </material>
      </visual>
    </link>
    <joint name='FR_HR_JOINT' type='revolute'>
      <child>FR_HIP</child>
      <parent>BODY</parent>
      <axis>
        <xyz>1 0 0</xyz>
        <limit>
          <lower>-1e+16</lower>
          <upper>1e+16</upper>
        </limit>
        <dynamics>
          <spring_reference>0</spring_reference>
          <spring_stiffness>0</spring_stiffness>
        </dynamics>
        <use_parent_model_frame>1</use_parent_model_frame>
      </axis>
    </joint>
    <link name='FR_THIGH'>
      <pose frame=''>0.35 -0.21992 0 0 -0 0</pose>
      <inertial>
        <pose frame=''>-0.00018 0.01146 -0.02836 0 -0 0</pose>
        <mass>3.32</mass>
        <inertia>
          <ixx>0.02493</ixx>
          <ixy>-3e-05</ixy>
          <ixz>-2e-05</ixz>
          <iyy>0.02533</iyy>
          <iyz>0.001</iyz>
          <izz>0.00394</izz>
        </inertia>
      </inertial>
      <!--collision name='FR_THIGH_collision'>
        <pose frame=''>0 0 0 0 -0 0</pose>
        <geometry>
          <mesh>
            <scale>1 1 1</scale>
            <uri>model://PONGBOT_Q_V6/meshes/FR_THIGH.STL</uri>
          </mesh>
        </geometry>
      </collision-->
      <visual name='FR_THIGH_visual'>
        <pose frame=''>0 0 0 0 -0 0</pose>
        <geometry>
          <mesh>
            <scale>1 1 1</scale>
            <uri>model://PONGBOT_Q_V6/meshes/FR_THIGH.STL</uri>
          </mesh>
        </geometry>
        <material>
          <ambient>213 0 0 1</ambient>
          <diffuse>1 1 1 1</diffuse>
          <emissive>0 0 0 1</emissive>
          <specular>0 0 0 0</specular>
        </material>
      </visual>
    </link>
    <joint name='FR_HP_JOINT' type='revolute'>
      <child>FR_THIGH</child>
      <parent>FR_HIP</parent>
      <axis>
        <xyz>0 1 0</xyz>
        <limit>
          <lower>-1e+16</lower>
          <upper>1e+16</upper>
        </limit>
        <dynamics>
          <spring_reference>0</spring_reference>
          <spring_stiffness>0</spring_stiffness>
        </dynamics>
        <use_parent_model_frame>1</use_parent_model_frame>
      </axis>
    </joint>
    <link name='FR_CALF'>
      <pose frame=''>0.35 -0.21992 -0.305 0 -0 0</pose>
      <inertial>
        <pose frame=''>0.03376 -0.00334 -0.0746 0 -0 0</pose>
        <mass>0.57335</mass>
        <inertia>
          <ixx>0.00434</ixx>
          <ixy>7e-05</ixy>
          <ixz>-0.00216</ixz>
          <iyy>0.00538</iyy>
          <iyz>-0.00018</iyz>
          <izz>0.00139</izz>
        </inertia>
      </inertial>
      <!--collision name='FR_CALF_collision'>
        <pose frame=''>0 0 0 0 -0 0</pose>
        <geometry>
          <mesh>
            <scale>1 1 1</scale>
            <uri>model://PONGBOT_Q_V6/meshes/FR_CALF.STL</uri>
          </mesh>
        </geometry>
      </collision-->
      <visual name='FR_CALF_visual'>
        <pose frame=''>0 0 0 0 -0 0</pose>
        <geometry>
          <mesh>
            <scale>1 1 1</scale>
            <uri>model://PONGBOT_Q_V6/meshes/FR_CALF.STL</uri>
          </mesh>
        </geometry>
        <material>
          <ambient>33 33 33 1</ambient>
          <diffuse>1 1 1 1</diffuse>
          <emissive>0 0 0 1</emissive>
          <specular>0 0 0 0</specular>
        </material>
      </visual>
    </link>
    <joint name='FR_KN_JOINT' type='revolute'>
      <child>FR_CALF</child>
      <parent>FR_THIGH</parent>
      <axis>
        <xyz>0 1 0</xyz>
        <limit>
          <lower>-1e+16</lower>
          <upper>1e+16</upper>
        </limit>
        <dynamics>
          <spring_reference>0</spring_reference>
          <spring_stiffness>0</spring_stiffness>
        </dynamics>
        <use_parent_model_frame>1</use_parent_model_frame>
      </axis>
    </joint>
    <link name='FR_TIP'>
      <pose frame=''>0.46836 -0.21992 -0.56773 0 -0 0</pose>
      <inertial>
        <pose frame=''>-0.00076 0 0.00289 0 -0 0</pose>
        <mass>0.1646</mass>
        <inertia>
          <ixx>9e-05</ixx>
          <ixy>0</ixy>
          <ixz>-1e-05</ixz>
          <iyy>9e-05</iyy>
          <iyz>0</iyz>
          <izz>8e-05</izz>
        </inertia>
      </inertial>
      <collision name='FR_TIP_collision'>
        <pose frame=''>0 0 0 1.57 -0 0</pose>
        <geometry>
	<cylinder>
	  <radius>0.029</radius>
	  <length>0.054</length>
	</cylinder>
          <!--mesh>
            <scale>1 1 1</scale>
            <uri>model://PONGBOT_Q_V6/meshes/FR_TIP.STL</uri>
          </mesh-->
        </geometry>
        <surface>
          <bounce>
            <restitution_coefficient> 0 </restitution_coefficient>
          </bounce>
          <friction>
            <ode>
               <mu>  1  </mu>
              <mu2> 1  </mu2>
            </ode>
          </friction>
          <contact>
            <ode>
              <!-- <soft_erp> 0.1 </soft_erp>
              <soft_cfm> 1E-4 </soft_cfm> -->
              <kp>5000000</kp>
              <kd>5000</kd>
               <max_vel>0.1</max_vel>
              <!-- <max_vel>0.01</max_vel> -->
               <min_depth>0.0001</min_depth>
              <!-- <min_depth>0.000</min_depth> -->
            </ode>
          </contact>
        </surface>
      </collision>
      <visual name='FR_TIP_visual'>
        <pose frame=''>0 0 0 0 -0 0</pose>
        <geometry>
          <mesh>
            <scale>1 1 1</scale>
            <uri>model://PONGBOT_Q_V6/meshes/FR_TIP.STL</uri>
          </mesh>
        </geometry>
      </visual>
      <sensor name="FR_TIP_contact" type='contact'>
       <contact>
         <collision>FR_TIP_collision</collision>
       </contact>
      </sensor>
    </link>
    <joint name='FR_TIP_JOINT' type='fixed'>
      <child>FR_TIP</child>
      <parent>FR_CALF</parent>
      <sensor name="FR_FT_SENSOR" type="force_torque">
        <force_torque>
          <frame>child</frame>
          <measure_direction>child_to_parent</measure_direction>
        </force_torque>
        <!-- <visualize> True </visualize> -->
      </sensor>
    </joint>
    <link name='RL_HIP'>
      <pose frame=''>-0.35 0.11502 0 0 -0 0</pose>
      <inertial>
        <pose frame=''>-0.00113 -0.00546 -0.00059 0 -0 0</pose>
        <mass>1.5346</mass>
        <inertia>
          <ixx>0.00131</ixx>
          <ixy>0</ixy>
          <ixz>1e-05</ixz>
          <iyy>0.00176</iyy>
          <iyz>1e-05</iyz>
          <izz>0.00141</izz>
        </inertia>
      </inertial>
      <!--collision name='RL_HIP_collision'>
        <pose frame=''>0 0 0 0 -0 0</pose>
        <geometry>
          <mesh>
            <scale>1 1 1</scale>
            <uri>model://PONGBOT_Q_V6/meshes/RL_HIP.STL</uri>
          </mesh>
        </geometry>
      </collision-->
      <visual name='RL_HIP_visual'>
        <pose frame=''>0 0 0 0 -0 0</pose>
        <geometry>
          <mesh>
            <scale>1 1 1</scale>
            <uri>model://PONGBOT_Q_V6/meshes/RL_HIP.STL</uri>
          </mesh>
        </geometry>
        <material>
          <ambient>213 0 0 1</ambient>
          <diffuse>1 1 1 1</diffuse>
          <emissive>0 0 0 1</emissive>
          <specular>0 0 0 0</specular>
        </material>
      </visual>
    </link>
    <joint name='RL_HR_JOINT' type='revolute'>
      <child>RL_HIP</child>
      <parent>BODY</parent>
      <axis>
        <xyz>1 0 0</xyz>
        <limit>
          <lower>-1e+16</lower>
          <upper>1e+16</upper>
        </limit>
        <dynamics>
          <spring_reference>0</spring_reference>
          <spring_stiffness>0</spring_stiffness>
        </dynamics>
        <use_parent_model_frame>1</use_parent_model_frame>
      </axis>
    </joint>
    <link name='RL_THIGH'>
      <pose frame=''>-0.35 0.21992 0 0 -0 0</pose>
      <inertial>
        <pose frame=''>0.00018 -0.01146 -0.02836 0 -0 0</pose>
        <mass>3.32</mass>
        <inertia>
          <ixx>0.02493</ixx>
          <ixy>-3e-05</ixy>
          <ixz>2e-05</ixz>
          <iyy>0.02533</iyy>
          <iyz>-0.001</iyz>
          <izz>0.00394</izz>
        </inertia>
      </inertial>
      <!--collision name='RL_THIGH_collision'>
        <pose frame=''>0 0 0 0 -0 0</pose>
        <geometry>
          <mesh>
            <scale>1 1 1</scale>
            <uri>model://PONGBOT_Q_V6/meshes/RL_THIGH.STL</uri>
          </mesh>
        </geometry>
      </collision-->
      <visual name='RL_THIGH_visual'>
        <pose frame=''>0 0 0 0 -0 0</pose>
        <geometry>
          <mesh>
            <scale>1 1 1</scale>
            <uri>model://PONGBOT_Q_V6/meshes/RL_THIGH.STL</uri>
          </mesh>
        </geometry>
        <material>
          <ambient>213 0 0 1</ambient>
          <diffuse>1 1 1 1</diffuse>
          <emissive>0 0 0 1</emissive>
          <specular>0 0 0 0</specular>
        </material>
      </visual>
    </link>
    <joint name='RL_HP_JOINT' type='revolute'>
      <child>RL_THIGH</child>
      <parent>RL_HIP</parent>
      <axis>
        <xyz>0 1 0</xyz>
        <limit>
          <lower>-1e+16</lower>
          <upper>1e+16</upper>
        </limit>
        <dynamics>
          <spring_reference>0</spring_reference>
          <spring_stiffness>0</spring_stiffness>
        </dynamics>
        <use_parent_model_frame>1</use_parent_model_frame>
      </axis>
    </joint>
    <link name='RL_CALF'>
      <pose frame=''>-0.35 0.21992 -0.305 0 -0 0</pose>
      <inertial>
        <pose frame=''>0.03375 0.00334 -0.0746 0 -0 0</pose>
        <mass>0.57335</mass>
        <inertia>
          <ixx>0.00434</ixx>
          <ixy>-7e-05</ixy>
          <ixz>-0.0021615</ixz>
          <iyy>0.00538</iyy>
          <iyz>0.00018</iyz>
          <izz>0.00139</izz>
        </inertia>
      </inertial>
      <!--collision name='RL_CALF_collision'>
        <pose frame=''>0 0 0 0 -0 0</pose>
        <geometry>
          <mesh>
            <scale>1 1 1</scale>
            <uri>model://PONGBOT_Q_V6/meshes/RL_CALF.STL</uri>
          </mesh>
        </geometry>
      </collision-->
      <visual name='RL_CALF_visual'>
        <pose frame=''>0 0 0 0 -0 0</pose>
        <geometry>
          <mesh>
            <scale>1 1 1</scale>
            <uri>model://PONGBOT_Q_V6/meshes/RL_CALF.STL</uri>
          </mesh>
        </geometry>
        <material>
          <ambient>33 33 33 1</ambient>
          <diffuse>1 1 1 1</diffuse>
          <emissive>0 0 0 1</emissive>
          <specular>0 0 0 0</specular>
        </material>
      </visual>
    </link>
    <joint name='RL_KN_JOINT' type='revolute'>
      <child>RL_CALF</child>
      <parent>RL_THIGH</parent>
      <axis>
        <xyz>0 1 0</xyz>
        <limit>
          <lower>-1e+16</lower>
          <upper>1e+16</upper>
        </limit>
        <dynamics>
          <spring_reference>0</spring_reference>
          <spring_stiffness>0</spring_stiffness>
        </dynamics>
        <use_parent_model_frame>1</use_parent_model_frame>
      </axis>
    </joint>
    <link name='RL_TIP'>
      <pose frame=''>-0.23164 0.21992 -0.56773 0 -0 0</pose>
      <inertial>
        <pose frame=''>-0.00076 0 0.00289 0 -0 0</pose>
        <mass>0.1646</mass>
        <inertia>
          <ixx>9e-05</ixx>
          <ixy>0</ixy>
          <ixz>-1e-05</ixz>
          <iyy>9e-05</iyy>
          <iyz>0</iyz>
          <izz>8e-05</izz>
        </inertia>
      </inertial>
      <collision name='RL_TIP_collision'>
        <pose frame=''>0 0 0 1.57 -0 0</pose>
        <geometry>
	<cylinder>
	  <radius>0.029</radius>
	  <length>0.054</length>
	</cylinder>
          <!--mesh>
            <scale>1 1 1</scale>
            <uri>model://PONGBOT_Q_V6/meshes/RL_TIP.STL</uri>
          </mesh-->
        </geometry>
        <surface>
          <bounce>
            <restitution_coefficient> 0 </restitution_coefficient>
          </bounce>
          <friction>
            <ode>
               <mu>  1  </mu>
              <mu2> 1  </mu2>
            </ode>
          </friction>
          <contact>
            <ode>
              <!-- <soft_erp> 0.1 </soft_erp>
              <soft_cfm> 1E-4 </soft_cfm> -->
              <kp>5000000</kp>
              <kd>5000</kd> -->
               <max_vel>0.1</max_vel>
              <!-- <max_vel>0.01</max_vel> -->
               <min_depth>0.0001</min_depth>
              <!-- <min_depth>0.0</min_depth> -->
            </ode>
          </contact>
        </surface>
      </collision>
      <visual name='RL_TIP_visual'>
        <pose frame=''>0 0 0 0 -0 0</pose>
        <geometry>
          <mesh>
            <scale>1 1 1</scale>
            <uri>model://PONGBOT_Q_V6/meshes/RL_TIP.STL</uri>
          </mesh>
        </geometry>
      </visual>
      <sensor name="RL_TIP_contact" type='contact'>
       <contact>
         <collision>RL_TIP_collision</collision>
       </contact>
      </sensor>
    </link>
    <joint name='RL_TIP_JOINT' type='fixed'>
      <child>RL_TIP</child>
      <parent>RL_CALF</parent>
      <sensor name="RL_FT_SENSOR" type="force_torque">
        <force_torque>
          <frame>child</frame>
          <measure_direction>child_to_parent</measure_direction>
        </force_torque>
        <!-- <visualize> True </visualize> -->
      </sensor>      
    </joint>
    <link name='RR_HIP'>
      <pose frame=''>-0.35 -0.11502 0 0 -0 0</pose>
      <inertial>
        <pose frame=''>-0.00113 0.00546 0.00059 0 -0 0</pose>
        <mass>1.5346</mass>
        <inertia>
          <ixx>0.00131</ixx>
          <ixy>0</ixy>
          <ixz>-1e-05</ixz>
          <iyy>0.00176</iyy>
          <iyz>1e-05</iyz>
          <izz>0.00141</izz>
        </inertia>
      </inertial>
      <!--collision name='RR_HIP_collision'>
        <pose frame=''>0 0 0 0 -0 0</pose>
        <geometry>
          <mesh>
            <scale>1 1 1</scale>
            <uri>model://PONGBOT_Q_V6/meshes/RR_HIP.STL</uri>
          </mesh>
        </geometry>
      </collision-->
      <visual name='RR_HIP_visual'>
        <pose frame=''>0 0 0 0 -0 0</pose>
        <geometry>
          <mesh>
            <scale>1 1 1</scale>
            <uri>model://PONGBOT_Q_V6/meshes/RR_HIP.STL</uri>
          </mesh>
        </geometry>
        <material>
          <ambient>213 0 0 1</ambient>
          <diffuse>1 1 1 1</diffuse>
          <emissive>0 0 0 1</emissive>
          <specular>0 0 0 0</specular>
        </material>
      </visual>
    </link>
    <joint name='RR_HR_JOINT' type='revolute'>
      <child>RR_HIP</child>
      <parent>BODY</parent>
      <axis>
        <xyz>1 0 0</xyz>
        <limit>
          <lower>-1e+16</lower>
          <upper>1e+16</upper>
        </limit>
        <dynamics>
          <spring_reference>0</spring_reference>
          <spring_stiffness>0</spring_stiffness>
        </dynamics>
        <use_parent_model_frame>1</use_parent_model_frame>
      </axis>
    </joint>
    <link name='RR_THIGH'>
      <pose frame=''>-0.35 -0.21992 0 0 -0 0</pose>
      <inertial>
        <pose frame=''>-0.00018 0.01146 -0.02836 0 -0 0</pose>
        <mass>3.32</mass>
        <inertia>
          <ixx>0.02493</ixx>
          <ixy>-3e-05</ixy>
          <ixz>-2e-05</ixz>
          <iyy>0.028</iyy>
          <iyz>0.001</iyz>
          <izz>0.00394</izz>
        </inertia>
      </inertial>
      <!--collision name='RR_THIGH_collision'>
        <pose frame=''>0 0 0 0 -0 0</pose>
        <geometry>
          <mesh>
            <scale>1 1 1</scale>
            <uri>model://PONGBOT_Q_V6/meshes/RR_THIGH.STL</uri>
          </mesh>
        </geometry>
      </collision-->
      <visual name='RR_THIGH_visual'>
        <pose frame=''>0 0 0 0 -0 0</pose>
        <geometry>
          <mesh>
            <scale>1 1 1</scale>
            <uri>model://PONGBOT_Q_V6/meshes/RR_THIGH.STL</uri>
          </mesh>
        </geometry>
        <material>
          <ambient>213 0 0 1</ambient>
          <diffuse>1 1 1 1</diffuse>
          <emissive>0 0 0 1</emissive>
          <specular>0 0 0 0</specular>
        </material>
      </visual>
    </link>
    <joint name='RR_HP_JOINT' type='revolute'>
      <child>RR_THIGH</child>
      <parent>RR_HIP</parent>
      <axis>
        <xyz>0 1 0</xyz>
        <limit>
          <lower>-1e+16</lower>
          <upper>1e+16</upper>
        </limit>
        <dynamics>
          <spring_reference>0</spring_reference>
          <spring_stiffness>0</spring_stiffness>
        </dynamics>
        <use_parent_model_frame>1</use_parent_model_frame>
      </axis>
    </joint>
    <link name='RR_CALF'>
      <pose frame=''>-0.35 -0.21992 -0.305 0 -0 0</pose>
      <inertial>
        <pose frame=''>0.03376 -0.00334 -0.0746 0 -0 0</pose>
        <mass>0.57335</mass>
        <inertia>
          <ixx>0.00434</ixx>
          <ixy>7e-05</ixy>
          <ixz>-0.00216</ixz>
          <iyy>0.00538</iyy>
          <iyz>-0.00018</iyz>
          <izz>0.00139</izz>
        </inertia>
      </inertial>
      <!--collision name='RR_CALF_collision'>
        <pose frame=''>0 0 0 0 -0 0</pose>
        <geometry>
          <mesh>
            <scale>1 1 1</scale>
            <uri>model://PONGBOT_Q_V6/meshes/RR_CALF.STL</uri>
          </mesh>
        </geometry>
      </collision-->
      <visual name='RR_CALF_visual'>
        <pose frame=''>0 0 0 0 -0 0</pose>
        <geometry>
          <mesh>
            <scale>1 1 1</scale>
            <uri>model://PONGBOT_Q_V6/meshes/RR_CALF.STL</uri>
          </mesh>
        </geometry>
        <material>
          <ambient>33 33 33 1</ambient>
          <diffuse>1 1 1 1</diffuse>
          <emissive>0 0 0 1</emissive>
          <specular>0 0 0 0</specular>
        </material>
      </visual>
    </link>
    <joint name='RR_KN_JOINT' type='revolute'>
      <child>RR_CALF</child>
      <parent>RR_THIGH</parent>
      <axis>
        <xyz>0 1 0</xyz>
        <limit>
          <lower>-1e+16</lower>
          <upper>1e+16</upper>
        </limit>
        <dynamics>
          <spring_reference>0</spring_reference>
          <spring_stiffness>0</spring_stiffness>
        </dynamics>
        <use_parent_model_frame>1</use_parent_model_frame>
      </axis>
    </joint>
    <link name='RR_TIP'>
      <pose frame=''>-0.23164 -0.21992 -0.56773 0 -0 0</pose>
      <inertial>
        <pose frame=''>-0.00076 0 0.00289 0 -0 0</pose>
        <mass>0.1646</mass>
        <inertia>
          <ixx>9e-05</ixx>
          <ixy>0</ixy>
          <ixz>-1e-05</ixz>
          <iyy>9e-05</iyy>
          <iyz>0</iyz>
          <izz>8e-05</izz>
        </inertia>
      </inertial>
      <collision name='RR_TIP_collision'>
        <pose frame=''>0 0 0 1.57 -0 0</pose>
        <geometry>
	<cylinder>
	  <radius>0.029</radius>
	  <length>0.054</length>
	</cylinder>
        </geometry>
        <surface>
          <bounce>
            <restitution_coefficient> 0 </restitution_coefficient>
          </bounce>
          <friction>
            <ode>
               <mu>  1  </mu>
              <mu2> 1  </mu2>
            </ode>
          </friction>
          <contact>
            <ode>
              <!-- <soft_erp> 0.1 </soft_erp>
              <soft_cfm> 1E-4 </soft_cfm> -->
              <kp>5000000</kp>
              <kd>5000</kd>
              <max_vel>0.1</max_vel>
              <!-- <max_vel>0.01</max_vel> -->
              <min_depth>0.0001</min_depth>
              <!-- <min_depth>0.</min_depth> -->
            </ode>
          </contact>
        </surface>
      </collision>
      <visual name='RR_TIP_visual'>
        <pose frame=''>0 0 0 0 -0 0</pose>
        <geometry>
          <mesh>
            <scale>1 1 1</scale>
            <uri>model://PONGBOT_Q_V6/meshes/RR_TIP.STL</uri>
          </mesh>
        </geometry>
      </visual>
      <sensor name="RR_TIP_contact" type='contact'>
       <contact>
         <collision>RR_TIP_collision</collision>
       </contact>
      </sensor>
    </link>
    <joint name='RR_TIP_JOINT' type='fixed'>
      <child>RR_TIP</child>
      <parent>RR_CALF</parent>
      <sensor name="RR_FT_SENSOR" type="force_torque">
        <force_torque>
          <frame>child</frame>
          <measure_direction>child_to_parent</measure_direction>
        </force_torque>
        <!-- <visualize> True </visualize> -->
      </sensor>
    </joint>
  </model>
</sdf>
