<?xml version="1.0" encoding="utf-8"?>
<!-- This URDF was automatically created by SolidWorks to URDF Exporter! Originally created by Stephen Brawner (brawner@gmail.com)
Commit Version: 1.5.1-0-g916b5db  Build Version: 1.5.7152.31018
For more information, please see http://wiki.ros.org/sw_urdf_exporter -->
<robot
    name="PONGBOT_Q_V6_rviz">
    <link
        name="BODY">
        <inertial>
            <origin
                xyz="-0.0221 0.00034 0.05293"
                rpy="0 0 0" />
            <mass
                value="24.701" />
            <inertia
                ixx="0.34089"
                ixy="-0.00272"
                ixz="-0.08697"
                iyy="1.8849"
                iyz="0.00032"
                izz="1.9898" />
        </inertial>
        <visual>
            <origin
                xyz="0 0 0"
                rpy="0 0 0" />
            <geometry>
                <mesh
                    filename="package://PONGBOT_Q_V6_rviz/meshes/BODY.STL" />
            </geometry>
            <material
                name="">
                <color
                    rgba="0.75294 0.75294 0.75294 1" />
            </material>
        </visual>
        <collision>
            <origin
                xyz="0 0 0"
                rpy="0 0 0" />
            <geometry>
                <mesh
                    filename="package://PONGBOT_Q_V6_rviz/meshes/BODY.STL" />
            </geometry>
        </collision>
    </link>
    <link
        name="RL_HIP">
        <inertial>
            <origin
                xyz="-0.00113 -0.00546 -0.00059"
                rpy="0 0 0" />
            <mass
                value="1.5346" />
            <inertia
                ixx="0.00131"
                ixy="0"
                ixz="1E-05"
                iyy="0.00176"
                iyz="1E-05"
                izz="0.00141" />
        </inertial>
        <visual>
            <origin
                xyz="0 0 0"
                rpy="0 0 0" />
            <geometry>
                <mesh
                    filename="package://PONGBOT_Q_V6_rviz/meshes/RL_HIP.STL" />
            </geometry>
            <material
                name="">
                <color
                    rgba="0.75294 0.75294 0.75294 1" />
            </material>
        </visual>
        <collision>
            <origin
                xyz="0 0 0"
                rpy="0 0 0" />
            <geometry>
                <mesh
                    filename="package://PONGBOT_Q_V6_rviz/meshes/RL_HIP.STL" />
            </geometry>
        </collision>
    </link>
    <joint
        name="1_RL_HR_JOINT"
        type="continuous">
        <origin
            xyz="-0.35 0.11502 0"
            rpy="0 0 0" />
        <parent
            link="BODY" />
        <child
            link="RL_HIP" />
        <axis
            xyz="1 0 0" />
    </joint>
    <link
        name="RL_THIGH">
        <inertial>
            <origin
                xyz="0.00018 -0.01146 -0.02836"
                rpy="0 0 0" />
            <mass
                value="3.32" />
            <inertia
                ixx="0.02493"
                ixy="-3E-05"
                ixz="2E-05"
                iyy="0.02533"
                iyz="-0.001"
                izz="0.00394" />
        </inertial>
        <visual>
            <origin
                xyz="0 0 0"
                rpy="0 0 0" />
            <geometry>
                <mesh
                    filename="package://PONGBOT_Q_V6_rviz/meshes/RL_THIGH.STL" />
            </geometry>
            <material
                name="">
                <color
                    rgba="0.75294 0.75294 0.75294 1" />
            </material>
        </visual>
        <collision>
            <origin
                xyz="0 0 0"
                rpy="0 0 0" />
            <geometry>
                <mesh
                    filename="package://PONGBOT_Q_V6_rviz/meshes/RL_THIGH.STL" />
            </geometry>
        </collision>
    </link>
    <joint
        name="RL_HP_JOINT"
        type="continuous">
        <origin
            xyz="0 0.1049 0"
            rpy="0 0 0" />
        <parent
            link="RL_HIP" />
        <child
            link="RL_THIGH" />
        <axis
            xyz="0 1 0" />
    </joint>
    <link
        name="RL_CALF">
        <inertial>
            <origin
                xyz="0.03375 0.00334 -0.0746"
                rpy="0 0 0" />
            <mass
                value="0.57335" />
            <inertia
                ixx="0.00434"
                ixy="-7E-05"
                ixz="-0.0021615"
                iyy="0.00538"
                iyz="0.00018"
                izz="0.00139" />
        </inertial>
        <visual>
            <origin
                xyz="0 0 0"
                rpy="0 0 0" />
            <geometry>
                <mesh
                    filename="package://PONGBOT_Q_V6_rviz/meshes/RL_CALF.STL" />
            </geometry>
            <material
                name="">
                <color
                    rgba="0.89804 0.91765 0.92941 1" />
            </material>
        </visual>
        <collision>
            <origin
                xyz="0 0 0"
                rpy="0 0 0" />
            <geometry>
                <mesh
                    filename="package://PONGBOT_Q_V6_rviz/meshes/RL_CALF.STL" />
            </geometry>
        </collision>
    </link>
    <joint
        name="RL_KN_JOINT"
        type="continuous">
        <origin
            xyz="0 0 -0.305"
            rpy="0 0 0" />
        <parent
            link="RL_THIGH" />
        <child
            link="RL_CALF" />
        <axis
            xyz="0 1 0" />
    </joint>
    <link
      name="RL_TIP">
      <inertial>
        <origin
          xyz="-0.00076 0 0.00289"
          rpy="0 0 0" />
        <mass
          value="0.1646" />
        <inertia
          ixx="9E-05"
          ixy="0"
          ixz="-1E-05"
          iyy="9E-05"
          iyz="0"
          izz="8E-05" />
      </inertial>
      <visual>
        <origin
          xyz="0 0 0"
          rpy="0 0 0" />
        <geometry>
          <mesh
            filename="package://PONGBOT_Q_V6_rviz/meshes/RL_TIP.STL" />
        </geometry>
        <material
          name="">
          <color
            rgba="0.75294 0.75294 0.75294 1" />
        </material>
      </visual>
      <collision>
        <origin
          xyz="0 0 0"
          rpy="0 0 0" />
        <geometry>
          <mesh
            filename="package://PONGBOT_Q_V6_rviz/meshes/RL_TIP.STL" />
        </geometry>
      </collision>
    </link>
    <joint
      name="RL_TIP_JOINT"
      type="fixed">
      <origin
        xyz="0.11836 0 -0.26273"
        rpy="0 0 0" />
      <parent
        link="RL_CALF" />
      <child
        link="RL_TIP" />
      <axis
        xyz="0 0 0" />
    </joint>
    <link
        name="RR_HIP">
        <inertial>
            <origin
                xyz="-0.00113 0.00546 0.00059"
                rpy="0 0 0" />
            <mass
                value="1.5346" />
            <inertia
                ixx="0.00131"
                ixy="0"
                ixz="-1E-05"
                iyy="0.00176"
                iyz="1E-05"
                izz="0.00141" />
        </inertial>
        <visual>
            <origin
                xyz="0 0 0"
                rpy="0 0 0" />
            <geometry>
                <mesh
                    filename="package://PONGBOT_Q_V6_rviz/meshes/RR_HIP.STL" />
            </geometry>
            <material
                name="">
                <color
                    rgba="0.75294 0.75294 0.75294 1" />
            </material>
        </visual>
        <collision>
            <origin
                xyz="0 0 0"
                rpy="0 0 0" />
            <geometry>
                <mesh
                    filename="package://PONGBOT_Q_V6_rviz/meshes/RR_HIP.STL" />
            </geometry>
        </collision>
    </link>
    <joint
        name="2_RR_HR_JOINT"
        type="continuous">
        <origin
            xyz="-0.35 -0.11502 0"
            rpy="0 0 0" />
        <parent
            link="BODY" />
        <child
            link="RR_HIP" />
        <axis
            xyz="1 0 0" />
    </joint>
    <link
        name="RR_THIGH">
        <inertial>
            <origin
                xyz="-0.00018 0.01146 -0.02836"
                rpy="0 0 0" />
            <mass
                value="3.32" />
            <inertia
                ixx="0.02493"
                ixy="-3E-05"
                ixz="-2E-05"
                iyy="0.028"
                iyz="0.001"
                izz="0.00394" />
        </inertial>
        <visual>
            <origin
                xyz="0 0 0"
                rpy="0 0 0" />
            <geometry>
                <mesh
                    filename="package://PONGBOT_Q_V6_rviz/meshes/RR_THIGH.STL" />
            </geometry>
            <material
                name="">
                <color
                    rgba="0.75294 0.75294 0.75294 1" />
            </material>
        </visual>
        <collision>
            <origin
                xyz="0 0 0"
                rpy="0 0 0" />
            <geometry>
                <mesh
                    filename="package://PONGBOT_Q_V6_rviz/meshes/RR_THIGH.STL" />
            </geometry>
        </collision>
    </link>
    <joint
        name="RR_HP_JOINT"
        type="continuous">
        <origin
            xyz="0 -0.1049 0"
            rpy="0 0 0" />
        <parent
            link="RR_HIP" />
        <child
            link="RR_THIGH" />
        <axis
            xyz="0 1 0" />
    </joint>
    <link
        name="RR_CALF">
        <inertial>
            <origin
                xyz="0.03376 -0.00334 -0.0746"
                rpy="0 0 0" />
            <mass
                value="0.57335" />
            <inertia
                ixx="0.00434"
                ixy="7E-05"
                ixz="-0.00216"
                iyy="0.00538"
                iyz="-0.00018"
                izz="0.00139" />
        </inertial>
        <visual>
            <origin
                xyz="0 0 0"
                rpy="0 0 0" />
            <geometry>
                <mesh
                    filename="package://PONGBOT_Q_V6_rviz/meshes/RR_CALF.STL" />
            </geometry>
            <material
                name="">
                <color
                    rgba="0.89804 0.91765 0.92941 1" />
            </material>
        </visual>
        <collision>
            <origin
                xyz="0 0 0"
                rpy="0 0 0" />
            <geometry>
                <mesh
                    filename="package://PONGBOT_Q_V6_rviz/meshes/RR_CALF.STL" />
            </geometry>
        </collision>
    </link>
    <joint
        name="RR_KN_JOINT"
        type="continuous">
        <origin
            xyz="0 0 -0.305"
            rpy="0 0 0" />
        <parent
            link="RR_THIGH" />
        <child
            link="RR_CALF" />
        <axis
            xyz="0 1 0" />
    </joint>
    <link
      name="RR_TIP">
      <inertial>
        <origin
          xyz="-0.00076 0 0.00289"
          rpy="0 0 0" />
        <mass
          value="0.1646" />
        <inertia
          ixx="9E-05"
          ixy="0"
          ixz="-1E-05"
          iyy="9E-05"
          iyz="0"
          izz="8E-05" />
      </inertial>
      <visual>
        <origin
          xyz="0 0 0"
          rpy="0 0 0" />
        <geometry>
          <mesh
            filename="package://PONGBOT_Q_V6_rviz/meshes/RR_TIP.STL" />
        </geometry>
        <material
          name="">
          <color
            rgba="0.75294 0.75294 0.75294 1" />
        </material>
      </visual>
      <collision>
        <origin
          xyz="0 0 0"
          rpy="0 0 0" />
        <geometry>
          <mesh
            filename="package://PONGBOT_Q_V6_rviz/meshes/RR_TIP.STL" />
        </geometry>
      </collision>
    </link>
    <joint
      name="RR_TIP_JOINT"
      type="fixed">
      <origin
        xyz="0.11836 0 -0.26273"
        rpy="0 0 0" />
      <parent
        link="RR_CALF" />
      <child
        link="RR_TIP" />
      <axis
        xyz="0 0 0" />
    </joint>
    <link
        name="FL_HIP">
        <inertial>
            <origin
                xyz="0.00113 -0.00546 0.00059"
                rpy="0 0 0" />
            <mass
                value="1.5346" />
            <inertia
                ixx="0.00131"
                ixy="0"
                ixz="1E-05"
                iyy="0.00176"
                iyz="-1E-05"
                izz="0.00141" />
        </inertial>
        <visual>
            <origin
                xyz="0 0 0"
                rpy="0 0 0" />
            <geometry>
                <mesh
                    filename="package://PONGBOT_Q_V6_rviz/meshes/FL_HIP.STL" />
            </geometry>
            <material
                name="">
                <color
                    rgba="0.75294 0.75294 0.75294 1" />
            </material>
        </visual>
        <collision>
            <origin
                xyz="0 0 0"
                rpy="0 0 0" />
            <geometry>
                <mesh
                    filename="package://PONGBOT_Q_V6_rviz/meshes/FL_HIP.STL" />
            </geometry>
        </collision>
    </link>
    <joint
        name="3_FL_HR_JOINT"
        type="continuous">
        <origin
            xyz="0.35 0.11502 0"
            rpy="0 0 0" />
        <parent
            link="BODY" />
        <child
            link="FL_HIP" />
        <axis
            xyz="1 0 0" />
    </joint>
    <link
        name="FL_THIGH">
        <inertial>
            <origin
                xyz="0.00018 -0.01146 -0.02836"
                rpy="0 0 0" />
            <mass
                value="3.32" />
            <inertia
                ixx="0.02493"
                ixy="-3E-05"
                ixz="2E-05"
                iyy="0.02533"
                iyz="-0.001"
                izz="0.00394" />
        </inertial>
        <visual>
            <origin
                xyz="0 0 0"
                rpy="0 0 0" />
            <geometry>
                <mesh
                    filename="package://PONGBOT_Q_V6_rviz/meshes/FL_THIGH.STL" />
            </geometry>
            <material
                name="">
                <color
                    rgba="0.75294 0.75294 0.75294 1" />
            </material>
        </visual>
        <collision>
            <origin
                xyz="0 0 0"
                rpy="0 0 0" />
            <geometry>
                <mesh
                    filename="package://PONGBOT_Q_V6_rviz/meshes/FL_THIGH.STL" />
            </geometry>
        </collision>
    </link>
    <joint
        name="FL_HP_JOINT"
        type="continuous">
        <origin
            xyz="0 0.1049 0"
            rpy="0 0 0" />
        <parent
            link="FL_HIP" />
        <child
            link="FL_THIGH" />
        <axis
            xyz="0 1 0" />
    </joint>
    <link
        name="FL_CALF">
        <inertial>
            <origin
                xyz="0.03375 0.00334 -0.0746"
                rpy="0 0 0" />
            <mass
                value="0.57335" />
            <inertia
                ixx="0.00434"
                ixy="-7E-05"
                ixz="-0.00216"
                iyy="0.00538"
                iyz="0.00018"
                izz="0.00139" />
        </inertial>
        <visual>
            <origin
                xyz="0 0 0"
                rpy="0 0 0" />
            <geometry>
                <mesh
                    filename="package://PONGBOT_Q_V6_rviz/meshes/FL_CALF.STL" />
            </geometry>
            <material
                name="">
                <color
                    rgba="0.89804 0.91765 0.92941 1" />
            </material>
        </visual>
        <collision>
            <origin
                xyz="0 0 0"
                rpy="0 0 0" />
            <geometry>
                <mesh
                    filename="package://PONGBOT_Q_V6_rviz/meshes/FL_CALF.STL" />
            </geometry>
        </collision>
    </link>
    <joint
        name="FL_KN_JOINT"
        type="continuous">
        <origin
            xyz="0 0 -0.305"
            rpy="0 0 0" />
        <parent
            link="FL_THIGH" />
        <child
            link="FL_CALF" />
        <axis
            xyz="0 1 0" />
    </joint>
    <link
      name="FL_TIP">
      <inertial>
        <origin
          xyz="-0.00076 0 0.00289"
          rpy="0 0 0" />
        <mass
          value="0.1646" />
        <inertia
          ixx="9E-05"
          ixy="0"
          ixz="-1E-05"
          iyy="9E-05"
          iyz="0"
          izz="8E-05" />
      </inertial>
      <visual>
        <origin
          xyz="0 0 0"
          rpy="0 0 0" />
        <geometry>
          <mesh
            filename="package://PONGBOT_Q_V6_rviz/meshes/FL_TIP.STL" />
        </geometry>
        <material
          name="">
          <color
            rgba="0.75294 0.75294 0.75294 1" />
        </material>
      </visual>
      <collision>
        <origin
          xyz="0 0 0"
          rpy="0 0 0" />
        <geometry>
          <mesh
            filename="package://PONGBOT_Q_V6_rviz/meshes/FL_TIP.STL" />
        </geometry>
      </collision>
    </link>
    <joint
      name="FL_TIP_JOINT"
      type="fixed">
      <origin
        xyz="0.11836 0 -0.26273"
        rpy="0 0 0" />
      <parent
        link="FL_CALF" />
      <child
        link="FL_TIP" />
      <axis
        xyz="0 0 0" />
    </joint>
    <link
        name="FR_HIP">
        <inertial>
            <origin
                xyz="0.00113 0.00546 -0.00059"
                rpy="0 0 0" />
            <mass
                value="1.5346" />
            <inertia
                ixx="0.00131"
                ixy="0"
                ixz="-1E-05"
                iyy="0.00176"
                iyz="-1E-05"
                izz="0.00141" />
        </inertial>
        <visual>
            <origin
                xyz="0 0 0"
                rpy="0 0 0" />
            <geometry>
                <mesh
                    filename="package://PONGBOT_Q_V6_rviz/meshes/FR_HIP.STL" />
            </geometry>
            <material
                name="">
                <color
                    rgba="0.75294 0.75294 0.75294 1" />
            </material>
        </visual>
        <collision>
            <origin
                xyz="0 0 0"
                rpy="0 0 0" />
            <geometry>
                <mesh
                    filename="package://PONGBOT_Q_V6_rviz/meshes/FR_HIP.STL" />
            </geometry>
        </collision>
    </link>
    <joint
        name="4_FR_HR_JOINT"
        type="continuous">
        <origin
            xyz="0.35 -0.11502 0"
            rpy="0 0 0" />
        <parent
            link="BODY" />
        <child
            link="FR_HIP" />
        <axis
            xyz="1 0 0" />
    </joint>
    <link
        name="FR_THIGH">
        <inertial>
            <origin
                xyz="-0.00018 0.01146 -0.02836"
                rpy="0 0 0" />
            <mass
                value="3.32" />
            <inertia
                ixx="0.02493"
                ixy="-3E-05"
                ixz="-2E-05"
                iyy="0.02533"
                iyz="0.001"
                izz="0.00394" />
        </inertial>
        <visual>
            <origin
                xyz="0 0 0"
                rpy="0 0 0" />
            <geometry>
                <mesh
                    filename="package://PONGBOT_Q_V6_rviz/meshes/FR_THIGH.STL" />
            </geometry>
            <material
                name="">
                <color
                    rgba="0.75294 0.75294 0.75294 1" />
            </material>
        </visual>
        <collision>
            <origin
                xyz="0 0 0"
                rpy="0 0 0" />
            <geometry>
                <mesh
                    filename="package://PONGBOT_Q_V6_rviz/meshes/FR_THIGH.STL" />
            </geometry>
        </collision>
    </link>
    <joint
        name="FR_HP_JOINT"
        type="continuous">
        <origin
            xyz="0 -0.1049 0"
            rpy="0 0 0" />
        <parent
            link="FR_HIP" />
        <child
            link="FR_THIGH" />
        <axis
            xyz="0 1 0" />
    </joint>
    <link
        name="FR_CALF">
        <inertial>
            <origin
                xyz="0.03376 -0.00334 -0.0746"
                rpy="0 0 0" />
            <mass
                value="0.57335" />
            <inertia
                ixx="0.00434"
                ixy="7E-05"
                ixz="-0.00216"
                iyy="0.00538"
                iyz="-0.00018"
                izz="0.00139" />
        </inertial>
        <visual>
            <origin
                xyz="0 0 0"
                rpy="0 0 0" />
            <geometry>
                <mesh
                    filename="package://PONGBOT_Q_V6_rviz/meshes/FR_CALF.STL" />
            </geometry>
            <material
                name="">
                <color
                    rgba="0.89804 0.91765 0.92941 1" />
            </material>
        </visual>
        <collision>
            <origin
                xyz="0 0 0"
                rpy="0 0 0" />
            <geometry>
                <mesh
                    filename="package://PONGBOT_Q_V6_rviz/meshes/FR_CALF.STL" />
            </geometry>
        </collision>
    </link>
    <joint
        name="FR_KN_JOINT"
        type="continuous">
        <origin
            xyz="0 0 -0.305"
            rpy="0 0 0" />
        <parent
            link="FR_THIGH" />
        <child
            link="FR_CALF" />
        <axis
            xyz="0 1 0" />
    </joint>
    <link
      name="FR_TIP">
      <inertial>
        <origin
          xyz="-0.00076 0 0.00289"
          rpy="0 0 0" />
        <mass
          value="0.1646" />
        <inertia
          ixx="9E-05"
          ixy="0"
          ixz="-1E-05"
          iyy="9E-05"
          iyz="0"
          izz="8E-05" />
      </inertial>
      <visual>
        <origin
          xyz="0 0 0"
          rpy="0 0 0" />
        <geometry>
          <mesh
            filename="package://PONGBOT_Q_V6_rviz/meshes/FR_TIP.STL" />
        </geometry>
        <material
          name="">
          <color
            rgba="0.75294 0.75294 0.75294 1" />
        </material>
      </visual>
      <collision>
        <origin
          xyz="0 0 0"
          rpy="0 0 0" />
        <geometry>
          <mesh
            filename="package://PONGBOT_Q_V6_rviz/meshes/FR_TIP.STL" />
        </geometry>
      </collision>
    </link>
    <joint
      name="FR_TIP_JOINT"
      type="fixed">
      <origin
        xyz="0.11836 0 -0.26273"
        rpy="0 0 0" />
      <parent
        link="FR_CALF" />
      <child
        link="FR_TIP" />
      <axis
        xyz="0 0 0" />
    </joint>
</robot>
