<robot
  name="PONGBOT_ONE_LEG">
  <link
    name="BASE">
    <inertial>
      <origin
        xyz="-0.048 0.063 -0.002"
        rpy="0 0 0" />
      <mass
        value="3.6" />
      <inertia
        ixx="0.017"
        ixy="-0.005"
        ixz="0"
        iyy="0.022"
        iyz="0.001"
        izz="0.034" />
    </inertial>
    <visual>
      <origin
        xyz="0 0 0"
        rpy="0 0 0" />
      <geometry>
        <mesh
          filename="package://PONGBOT_ONE_LEG/meshes/BASE.STL" />
      </geometry>
      <material
        name="">
        <color
          rgba="0.79216 0.81961 0.93333 1" />
      </material>
    </visual>
    <collision>
      <origin
        xyz="0 0 0"
        rpy="0 0 0" />
      <geometry>
        <mesh
          filename="package://PONGBOT_ONE_LEG/meshes/BASE.STL" />
      </geometry>
    </collision>
  </link>
  <link
    name="HIP">
    <inertial>
      <origin
        xyz="0.001 0.003 0"
        rpy="0 0 0" />
      <mass
        value="2.35" />
      <inertia
        ixx="0.002"
        ixy="0"
        ixz="0"
        iyy="0.002"
        iyz="0"
        izz="0.002" />
    </inertial>
    <visual>
      <origin
        xyz="0 0 0"
        rpy="0 0 0" />
      <geometry>
        <mesh
          filename="package://PONGBOT_ONE_LEG/meshes/HIP.STL" />
      </geometry>
      <material
        name="">
        <color
          rgba="0.79216 0.81961 0.93333 1" />
      </material>
    </visual>
    <collision>
      <origin
        xyz="0 0 0"
        rpy="0 0 0" />
      <geometry>
        <mesh
          filename="package://PONGBOT_ONE_LEG/meshes/HIP.STL" />
      </geometry>
    </collision>
  </link>
  <joint
    name="HR_JOINT"
    type="continuous">
    <origin
      xyz="0 0.1208 0"
      rpy="0 0 0" />
    <parent
      link="BASE" />
    <child
      link="HIP" />
    <axis
      xyz="1 0 0" />
  </joint>
  <link
    name="THIGH">
    <inertial>
      <origin
        xyz="0 -0.01 -0.037"
        rpy="0 0 0" />
      <mass
        value="3.15" />
      <inertia
        ixx="0.024"
        ixy="0"
        ixz="0"
        iyy="0.025"
        iyz="-0.001"
        izz="0.003" />
    </inertial>
    <visual>
      <origin
        xyz="0 0 0"
        rpy="0 0 0" />
      <geometry>
        <mesh
          filename="package://PONGBOT_ONE_LEG/meshes/THIGH.STL" />
      </geometry>
      <material
        name="">
        <color
          rgba="0.79216 0.81961 0.93333 1" />
      </material>
    </visual>
    <collision>
      <origin
        xyz="0 0 0"
        rpy="0 0 0" />
      <geometry>
        <mesh
          filename="package://PONGBOT_ONE_LEG/meshes/THIGH.STL" />
      </geometry>
    </collision>
  </link>
  <joint
    name="HP_JOINT"
    type="continuous">
    <origin
      xyz="0 0.105 0"
      rpy="0 0 0" />
    <parent
      link="HIP" />
    <child
      link="THIGH" />
    <axis
      xyz="0 1 0" />
  </joint>
  <link
    name="CALF">
    <inertial>
      <origin
        xyz="-0.001 -0.006 -0.081"
        rpy="0 0 0" />
      <mass
        value="0.35" />
      <inertia
        ixx="0.01"
        ixy="0"
        ixz="0"
        iyy="0.01"
        iyz="0"
        izz="0" />
    </inertial>
    <visual>
      <origin
        xyz="0 0 0"
        rpy="0 0 0" />
      <geometry>
        <mesh
          filename="package://PONGBOT_ONE_LEG/meshes/CALF.STL" />
      </geometry>
      <material
        name="">
        <color
          rgba="0.79216 0.81961 0.93333 1" />
      </material>
    </visual>
    <collision>
      <origin
        xyz="0 0 0"
        rpy="0 0 0" />
      <geometry>
        <mesh
          filename="package://PONGBOT_ONE_LEG/meshes/CALF.STL" />
      </geometry>
    </collision>
  </link>
  <joint
    name="KN_JOINT"
    type="continuous">
    <origin
      xyz="0 0 -0.305"
      rpy="0 0 0" />
    <parent
      link="THIGH" />
    <child
      link="CALF" />
    <axis
      xyz="0 1 0" />
  </joint>
  <link
    name="TIP">
    <inertial>
      <origin
        xyz="-0.005 0 -0.005"
        rpy="0 0 0" />
      <mass
        value="0.006" />
      <inertia
        ixx="0"
        ixy="0"
        ixz="0"
        iyy="0"
        iyz="0"
        izz="0" />
    </inertial>
    <visual>
      <origin
        xyz="0 0 0"
        rpy="0 0 0" />
      <geometry>
        <mesh
          filename="package://PONGBOT_ONE_LEG/meshes/TIP.STL" />
      </geometry>
      <material
        name="">
        <color
          rgba="1 0 0.098039 1" />
      </material>
    </visual>
    <collision>
      <origin
        xyz="0 0 0"
        rpy="0 0 0" />
      <geometry>
        <mesh
          filename="package://PONGBOT_ONE_LEG/meshes/TIP.STL" />
      </geometry>
    </collision>
  </link>
  <joint
    name="TIP_JOINT"
    type="fixed">
    <origin
      xyz="-0.013819 0 -0.29282"
      rpy="0 0 0" />
    <parent
      link="CALF" />
    <child
      link="TIP" />
    <axis
      xyz="0 0 0" />
  </joint>
</robot>
