<sdf version='1.6'>
  <model name='PONGBOT_ONE_LEG'>
    <link name='BASE'>
      <pose frame=''>0 0 0 0 -0 0</pose>
      <inertial>
        <pose frame=''>-0.048 0.063 -0.002 0 -0 0</pose>
        <mass>3.292</mass>
        <inertia>
          <ixx>0.017</ixx>
          <ixy>-0.005</ixy>
          <ixz>0</ixz>
          <iyy>0.022</iyy>
          <iyz>0.001</iyz>
          <izz>0.034</izz>
        </inertia>
      </inertial>
      <collision name='BASE_collision'>
        <pose frame=''>0 0 0 0 -0 0</pose>
        <geometry>
          <mesh>
            <scale>1 1 1</scale>
            <uri>model://PONGBOT_ONE_LEG/meshes/BASE.STL</uri>
          </mesh>
        </geometry>
      </collision>
      <visual name='BASE_visual'>
        <pose frame=''>0 0 0 0 -0 0</pose>
        <geometry>
          <mesh>
            <scale>1 1 1</scale>
            <uri>model://PONGBOT_ONE_LEG/meshes/BASE.STL</uri>
          </mesh>
        </geometry>
      </visual>
    </link>
    <link name='HIP'>
      <pose frame=''>0 0.1208 0 0 -0 0</pose>
      <inertial>
        <pose frame=''>0.001 0.003 0 0 -0 0</pose>
        <mass>1.53</mass>
        <inertia>
          <ixx>0.002</ixx>
          <ixy>0</ixy>
          <ixz>0</ixz>
          <iyy>0.002</iyy>
          <iyz>0</iyz>
          <izz>0.002</izz>
        </inertia>
      </inertial>
      <collision name='HIP_collision'>
        <pose frame=''>0 0 0 0 -0 0</pose>
        <geometry>
          <mesh>
            <scale>1 1 1</scale>
            <uri>model://PONGBOT_ONE_LEG/meshes/HIP.STL</uri>
          </mesh>
        </geometry>
      </collision>
      <visual name='HIP_visual'>
        <pose frame=''>0 0 0 0 -0 0</pose>
        <geometry>
          <mesh>
            <scale>1 1 1</scale>
            <uri>model://PONGBOT_ONE_LEG/meshes/HIP.STL</uri>
          </mesh>
        </geometry>
      </visual>
    </link>
    <joint name='HR_JOINT' type='revolute'>
      <child>HIP</child>
      <parent>BASE</parent>
      <axis>
        <xyz>1 0 0</xyz>
        <limit>
          <lower>-1e+16</lower>
          <upper>1e+16</upper>
        </limit>
        <dynamics>
          <spring_reference>0</spring_reference>
          <spring_stiffness>0</spring_stiffness>
        </dynamics>
        <use_parent_model_frame>1</use_parent_model_frame>
      </axis>
    </joint>
    <link name='THIGH'>
      <pose frame=''>0 0.2258 0 0 -0 0</pose>
      <inertial>
        <pose frame=''>0 -0.01 -0.037 0 -0 0</pose>
        <mass>3.306</mass>
        <inertia>
          <ixx>0.024</ixx>
          <ixy>0</ixy>
          <ixz>0</ixz>
          <iyy>0.025</iyy>
          <iyz>-0.001</iyz>
          <izz>0.003</izz>
        </inertia>
      </inertial>
      <collision name='THIGH_collision'>
        <pose frame=''>0 0 0 0 -0 0</pose>
        <geometry>
          <mesh>
            <scale>1 1 1</scale>
            <uri>model://PONGBOT_ONE_LEG/meshes/THIGH.STL</uri>
          </mesh>
        </geometry>
      </collision>
      <visual name='THIGH_visual'>
        <pose frame=''>0 0 0 0 -0 0</pose>
        <geometry>
          <mesh>
            <scale>1 1 1</scale>
            <uri>model://PONGBOT_ONE_LEG/meshes/THIGH.STL</uri>
          </mesh>
        </geometry>
      </visual>
    </link>
    <joint name='HP_JOINT' type='revolute'>
      <child>THIGH</child>
      <parent>HIP</parent>
      <axis>
        <xyz>0 1 0</xyz>
        <limit>
          <lower>-1e+16</lower>
          <upper>1e+16</upper>
        </limit>
        <dynamics>
          <spring_reference>0</spring_reference>
          <spring_stiffness>0</spring_stiffness>
        </dynamics>
        <use_parent_model_frame>1</use_parent_model_frame>
      </axis>
    </joint>
    <link name='CALF'>
      <pose frame=''>0 0.2258 -0.305 0 -0 0</pose>
      <inertial>
        <pose frame=''>-0.001 -0.006 -0.081 0 -0 0</pose>
        <mass>0.828</mass>
        <inertia>
          <ixx>0.01</ixx>
          <ixy>0</ixy>
          <ixz>0</ixz>
          <iyy>0.01</iyy>
          <iyz>0</iyz>
          <izz>0</izz>
        </inertia>
      </inertial>
      <collision name='CALF_collision'>
        <pose frame=''>0 0 0 0 -0 0</pose>
        <geometry>
          <mesh>
            <scale>1 1 1</scale>
            <uri>model://PONGBOT_ONE_LEG/meshes/CALF.STL</uri>
          </mesh>
        </geometry>
      </collision>
      <visual name='CALF_visual'>
        <pose frame=''>0 0 0 0 -0 0</pose>
        <geometry>
          <mesh>
            <scale>1 1 1</scale>
            <uri>model://PONGBOT_ONE_LEG/meshes/CALF.STL</uri>
          </mesh>
        </geometry>
      </visual>
    </link>
    <joint name='KN_JOINT' type='revolute'>
      <child>CALF</child>
      <parent>THIGH</parent>
      <axis>
        <xyz>0 1 0</xyz>
        <limit>
          <lower>-1e+16</lower>
          <upper>1e+16</upper>
        </limit>
        <dynamics>
          <spring_reference>0</spring_reference>
          <spring_stiffness>0</spring_stiffness>
        </dynamics>
        <use_parent_model_frame>1</use_parent_model_frame>
      </axis>
    </joint>
    <link name='TIP'>
      <pose frame=''>-0.013819 0.2258 -0.59782 0 -0 0</pose>
      <inertial>
        <pose frame=''>-0.005 0 -0.005 0 -0 0</pose>
        <mass>0.006</mass>
        <inertia>
          <ixx>0</ixx>
          <ixy>0</ixy>
          <ixz>0</ixz>
          <iyy>0</iyy>
          <iyz>0</iyz>
          <izz>0</izz>
        </inertia>
      </inertial>
      <collision name='TIP_collision'>
        <pose frame=''>0 0 0 0 -0 0</pose>
        <geometry>
          <mesh>
            <scale>1 1 1</scale>
            <uri>model://PONGBOT_ONE_LEG/meshes/TIP.STL</uri>
          </mesh>
        </geometry>
      </collision>
      <visual name='TIP_visual'>
        <pose frame=''>0 0 0 0 -0 0</pose>
        <geometry>
          <mesh>
            <scale>1 1 1</scale>
            <uri>model://PONGBOT_ONE_LEG/meshes/TIP.STL</uri>
          </mesh>
        </geometry>
      </visual>
    </link>
    <joint name='TIP_JOINT' type='fixed'>
      <child>TIP</child>
      <parent>CALF</parent>
    </joint>
  </model>
</sdf>
